<?xml version="1.0" encoding="utf-8"?>
<!-- This URDF was automatically created by SolidWorks to URDF Exporter! Originally created by Stephen Brawner (brawner@gmail.com) 
     Commit Version: 1.6.0-4-g7f85cfe  Build Version: 1.6.7995.38578
     For more information, please see http://wiki.ros.org/sw_urdf_exporter -->
<robot
  name="two_axis">
  <link name="world"></link>
  <joint name="world2base" type="fixed">
    <origin xyz="0.0 0.0 0.0" rpy="0.0 0.0 0.0"/>
    <parent link="world"/>
    <child link="base_link"/>
    <axis xyz="0.0 0.0 0.0"/>
    <limit lower="0.0" upper="0.0" effort="0.0" velocity="0.0"/>
  </joint>
  <link
    name="base_link">
    <inertial>
      <origin
        xyz="0.0058056 -0.11502 -0.018827"
        rpy="0 1.575 0 " />
      <mass
        value="1.0009" />
      <inertia
        ixx="0.0019754"
        ixy="-2.0507E-05"
        ixz="8.3623E-05"
        iyy="0.0031868"
        iyz="-2.7618E-05"
        izz="0.0049252" />
    </inertial>
    <visual>
      <origin
        xyz="0 0 0.5"
        rpy="1.575 0 0" />
      <geometry>
        <mesh
          filename="package://two_axis_description/meshes/base_link.STL" scale="0.01 0.01 0.01"/>
      </geometry>
      <material
        name="">
        <color
          rgba="0.0 1.0 0.0 1" />
      </material>
    </visual>
    <collision>
      <origin
        xyz="0 0 0"
        rpy="0 0 0" />
      <geometry>
        <mesh
          filename="package://two_axis_description/meshes/base_link.STL" />
      </geometry>
    </collision>
  </link>
  <link
    name="Link_1">
    <inertial>
      <mass
        value="0.12498" />
      <inertia
        ixx="8.0222E-05"
        ixy="-1.8195E-05"
        ixz="-3.1172E-05"
        iyy="9.7652E-05"
        iyz="-1.9655E-05"
        izz="7.1128E-05" />
    </inertial>
    <visual>
      <origin
        xyz="0.0057 0.768 -0.2787"
        rpy="1.575 -1.575 0" />
      <geometry>
        <mesh
          filename="package://two_axis_description/meshes/link_1.STL" scale="0.01 0.01 0.01"/>
      </geometry>
      <material
        name="">
        <color
          rgba="1 0 0 1" />
      </material>
    </visual>
    <collision>
      <origin
        xyz="0 0 0"
        rpy="0 0 0" />
      <geometry>
        <mesh
          filename="package://two_axis_description/meshes/link_1.STL" scale="0.01 0.01 0.01"/>
      </geometry>
    </collision>
  </link>
  <joint
    name="Joint_1"
    type="revolute">
    <origin
      xyz="0 0 1.32"
      rpy="0 0 0" />
    <parent
      link="base_link" />
    <child
      link="Link_1" />
    <axis
      xyz="0 1 0" />
    <limit
      lower="-1.57"
      upper="1.57"
      effort="0.147"
      velocity="87" />
  </joint>
  <link
    name="Link_2">
    <inertial>
      <origin
        xyz="-0.07 -0.18 0.0"
        rpy="0 0 0" />
      <mass
        value="0.13201" />
      <inertia
        ixx="8.5158E-05"
        ixy="-1.6278E-05"
        ixz="-2.9626E-06"
        iyy="6.6097E-05"
        iyz="-1.1804E-06"
        izz="8.3422E-05" />
    </inertial>
    <visual>
      <origin
        xyz="0.374 -0.118 0.001"
        rpy="0.0 0.0 0.0" />
      <geometry>
        <mesh
          filename="package://two_axis_description/meshes/link_2.STL" scale="0.01 0.01 0.01"/>
      </geometry>
      <material
        name="">
        <color
          rgba="0.79216 0.81961 0.93333 1" />
      </material>
    </visual>
    <collision>
      <origin
        xyz="0 0 0"
        rpy="0 0 0" />
      <geometry>
        <mesh
          filename="package://two_axis_description/meshes/link_2.STL" />
      </geometry>
    </collision>
  </link>
  <joint
    name="Joint_2"
    type="revolute">
    <origin
      xyz="0.020 1.05 -0.6"
      rpy="0 -1.575 0" />
    <parent
      link="Link_1" />
    <child
      link="Link_2" />
    <axis
      xyz="1 0 0" />
    <limit
      lower="-1.57"
      upper="1.57"
      effort="0.147"
      velocity="87" />
  </joint>
</robot>